<?xml version="1.0"?>


<robot name="yorat_wheel" xmlns:xacro="http://ros.org/wiki/xacro">

	<xacro:macro name="yorat_wheel" params="wheel_prefix *joint_pose">
		
		<link name="${wheel_prefix}_wheel_link">
			<inertial>
				<mass value="${wheel_mass}" />
				<origin xyz="0 0 0" />
				<inertia  ixx="0.02467" ixy="0" ixz="0" iyy="0.04411" iyz="0" izz="0.02467" />
			</inertial>
		
			<visual>
				<origin xyz="0 0 0" rpy="0 0 0" />
				<geometry>
	         		<cylinder length="${wheel_length}" radius="${wheel_radius}" />
	      		</geometry>
	      		<material name="">
    				<color rgba="${45/255} ${45/255} ${45/255} 1.0"/>
  				</material>
			</visual>
		
			<collision>
				<origin xyz="0 0 0" rpy="0 0 0" />
				<geometry>
					<cylinder length="${wheel_length}" radius="${wheel_radius}" />
				</geometry>
			</collision>
		</link>

		<gazebo reference="${wheel_prefix}_wheel_link">
			<material>Gazebo/DarkGrey</material>
			<mu1 value="1.0"/>
			<mu2 value="1.0"/>
			<kp value="10000000.0" />
			<kd value="1.0" />
			<fdir1 value="1 0 0"/>
		</gazebo>


		<joint name="${wheel_prefix}_wheel_joint" type="continuous">
			<parent link="base_link"/>
			<child link="${wheel_prefix}_wheel_link"/>
			<xacro:insert_block name="joint_pose"/>
			<axis xyz="0 0 -1" rpy="0 0 0" />
		</joint>


		<transmission name="${wheel_prefix}_wheel_trans" type="SimpleTransmission">
			<type>transmission_interface/SimpleTransmission</type>
			<actuator name="${wheel_prefix}_wheel_motor">
				<mechanicalReduction>1</mechanicalReduction>
			</actuator>

			<joint name="${wheel_prefix}_wheel_joint">
				<hardwareInterface>hardware_interface/VelocityJointInterface</hardwareInterface>
			</joint>
		</transmission>


	</xacro:macro>

</robot>